2019-09-16 13:20:05,186 ERROR: Exception on /news/ [GET] [in /mnt/f/python_lin/nail/env/lib/python3.6/site-packages/flask/app.py:1891]
Traceback (most recent call last):
  File "/mnt/f/python_lin/nail/env/lib/python3.6/site-packages/flask/app.py", line 2446, in wsgi_app
    response = self.full_dispatch_request()
  File "/mnt/f/python_lin/nail/env/lib/python3.6/site-packages/flask/app.py", line 1951, in full_dispatch_request
    rv = self.handle_user_exception(e)
  File "/mnt/f/python_lin/nail/env/lib/python3.6/site-packages/flask/app.py", line 1820, in handle_user_exception
    reraise(exc_type, exc_value, tb)
  File "/mnt/f/python_lin/nail/env/lib/python3.6/site-packages/flask/_compat.py", line 39, in reraise
    raise value
  File "/mnt/f/python_lin/nail/env/lib/python3.6/site-packages/flask/app.py", line 1949, in full_dispatch_request
    rv = self.dispatch_request()
  File "/mnt/f/python_lin/nail/env/lib/python3.6/site-packages/flask/app.py", line 1935, in dispatch_request
    return self.view_functions[rule.endpoint](**req.view_args)
  File "/mnt/f/python_lin/nail/app/news/routes.py", line 8, in index
    return render_template("news/index.html", news_list=news_list)
  File "/mnt/f/python_lin/nail/env/lib/python3.6/site-packages/flask/templating.py", line 140, in render_template
    ctx.app,
  File "/mnt/f/python_lin/nail/env/lib/python3.6/site-packages/flask/templating.py", line 120, in _render
    rv = template.render(context)
  File "/mnt/f/python_lin/nail/env/lib/python3.6/site-packages/jinja2/asyncsupport.py", line 76, in render
    return original_render(self, *args, **kwargs)
  File "/mnt/f/python_lin/nail/env/lib/python3.6/site-packages/jinja2/environment.py", line 1008, in render
    return self.environment.handle_exception(exc_info, True)
  File "/mnt/f/python_lin/nail/env/lib/python3.6/site-packages/jinja2/environment.py", line 780, in handle_exception
    reraise(exc_type, exc_value, tb)
  File "/mnt/f/python_lin/nail/env/lib/python3.6/site-packages/jinja2/_compat.py", line 37, in reraise
    raise value.with_traceback(tb)
  File "/mnt/f/python_lin/nail/app/templates/news/index.html", line 2, in top-level template code
    {% import 'bootstrap/wtf.html' as wtf %}
  File "/mnt/f/python_lin/nail/app/templates/base.html", line 1, in top-level template code
    {% extends 'bootstrap/base.html' %}
  File "/mnt/f/python_lin/nail/env/lib/python3.6/site-packages/flask_bootstrap/templates/bootstrap/base.html", line 1, in top-level template code
    {% block doc -%}
  File "/mnt/f/python_lin/nail/env/lib/python3.6/site-packages/flask_bootstrap/templates/bootstrap/base.html", line 4, in block "doc"
    {%- block html %}
  File "/mnt/f/python_lin/nail/env/lib/python3.6/site-packages/flask_bootstrap/templates/bootstrap/base.html", line 20, in block "html"
    {% block body -%}
  File "/mnt/f/python_lin/nail/env/lib/python3.6/site-packages/flask_bootstrap/templates/bootstrap/base.html", line 23, in block "body"
    {% block content -%}
  File "/mnt/f/python_lin/nail/app/templates/base.html", line 17, in block "content"
    {% block app_content %}
  File "/mnt/f/python_lin/nail/app/templates/news/index.html", line 6, in block "app_content"
    {% for news in news_list %}
TypeError: 'NoneType' object is not iterable
2019-09-16 13:22:49,467 INFO: Nail startup [in /mnt/f/python_lin/nail/app/__init__.py:89]
2019-09-16 13:22:52,379 ERROR: Exception on /news/ [GET] [in /mnt/f/python_lin/nail/env/lib/python3.6/site-packages/flask/app.py:1891]
Traceback (most recent call last):
  File "/mnt/f/python_lin/nail/env/lib/python3.6/site-packages/sqlalchemy/engine/base.py", line 1244, in _execute_context
    cursor, statement, parameters, context
  File "/mnt/f/python_lin/nail/env/lib/python3.6/site-packages/sqlalchemy/engine/default.py", line 552, in do_execute
    cursor.execute(statement, parameters)
sqlite3.IntegrityError: UNIQUE constraint failed: news.url

The above exception was the direct cause of the following exception:

Traceback (most recent call last):
  File "/mnt/f/python_lin/nail/env/lib/python3.6/site-packages/flask/app.py", line 2446, in wsgi_app
    response = self.full_dispatch_request()
  File "/mnt/f/python_lin/nail/env/lib/python3.6/site-packages/flask/app.py", line 1951, in full_dispatch_request
    rv = self.handle_user_exception(e)
  File "/mnt/f/python_lin/nail/env/lib/python3.6/site-packages/flask/app.py", line 1820, in handle_user_exception
    reraise(exc_type, exc_value, tb)
  File "/mnt/f/python_lin/nail/env/lib/python3.6/site-packages/flask/_compat.py", line 39, in reraise
    raise value
  File "/mnt/f/python_lin/nail/env/lib/python3.6/site-packages/flask/app.py", line 1949, in full_dispatch_request
    rv = self.dispatch_request()
  File "/mnt/f/python_lin/nail/env/lib/python3.6/site-packages/flask/app.py", line 1935, in dispatch_request
    return self.view_functions[rule.endpoint](**req.view_args)
  File "/mnt/f/python_lin/nail/app/news/routes.py", line 7, in index
    news_list = get_sevendays_news_manikur()
  File "/mnt/f/python_lin/nail/app/news/parser/sevendays_news_manikur.py", line 60, in get_sevendays_news_manikur
    save_news(title, url, published, source, text)
  File "/mnt/f/python_lin/nail/app/news/parser/sevendays_news_manikur.py", line 68, in save_news
    db.session.commit()
  File "/mnt/f/python_lin/nail/env/lib/python3.6/site-packages/sqlalchemy/orm/scoping.py", line 162, in do
    return getattr(self.registry(), name)(*args, **kwargs)
  File "/mnt/f/python_lin/nail/env/lib/python3.6/site-packages/sqlalchemy/orm/session.py", line 1027, in commit
    self.transaction.commit()
  File "/mnt/f/python_lin/nail/env/lib/python3.6/site-packages/sqlalchemy/orm/session.py", line 494, in commit
    self._prepare_impl()
  File "/mnt/f/python_lin/nail/env/lib/python3.6/site-packages/sqlalchemy/orm/session.py", line 473, in _prepare_impl
    self.session.flush()
  File "/mnt/f/python_lin/nail/env/lib/python3.6/site-packages/sqlalchemy/orm/session.py", line 2459, in flush
    self._flush(objects)
  File "/mnt/f/python_lin/nail/env/lib/python3.6/site-packages/sqlalchemy/orm/session.py", line 2597, in _flush
    transaction.rollback(_capture_exception=True)
  File "/mnt/f/python_lin/nail/env/lib/python3.6/site-packages/sqlalchemy/util/langhelpers.py", line 68, in __exit__
    compat.reraise(exc_type, exc_value, exc_tb)
  File "/mnt/f/python_lin/nail/env/lib/python3.6/site-packages/sqlalchemy/util/compat.py", line 153, in reraise
    raise value
  File "/mnt/f/python_lin/nail/env/lib/python3.6/site-packages/sqlalchemy/orm/session.py", line 2557, in _flush
    flush_context.execute()
  File "/mnt/f/python_lin/nail/env/lib/python3.6/site-packages/sqlalchemy/orm/unitofwork.py", line 422, in execute
    rec.execute(self)
  File "/mnt/f/python_lin/nail/env/lib/python3.6/site-packages/sqlalchemy/orm/unitofwork.py", line 589, in execute
    uow,
  File "/mnt/f/python_lin/nail/env/lib/python3.6/site-packages/sqlalchemy/orm/persistence.py", line 245, in save_obj
    insert,
  File "/mnt/f/python_lin/nail/env/lib/python3.6/site-packages/sqlalchemy/orm/persistence.py", line 1138, in _emit_insert_statements
    statement, params
  File "/mnt/f/python_lin/nail/env/lib/python3.6/site-packages/sqlalchemy/engine/base.py", line 988, in execute
    return meth(self, multiparams, params)
  File "/mnt/f/python_lin/nail/env/lib/python3.6/site-packages/sqlalchemy/sql/elements.py", line 287, in _execute_on_connection
    return connection._execute_clauseelement(self, multiparams, params)
  File "/mnt/f/python_lin/nail/env/lib/python3.6/site-packages/sqlalchemy/engine/base.py", line 1107, in _execute_clauseelement
    distilled_params,
  File "/mnt/f/python_lin/nail/env/lib/python3.6/site-packages/sqlalchemy/engine/base.py", line 1248, in _execute_context
    e, statement, parameters, cursor, context
  File "/mnt/f/python_lin/nail/env/lib/python3.6/site-packages/sqlalchemy/engine/base.py", line 1466, in _handle_dbapi_exception
    util.raise_from_cause(sqlalchemy_exception, exc_info)
  File "/mnt/f/python_lin/nail/env/lib/python3.6/site-packages/sqlalchemy/util/compat.py", line 398, in raise_from_cause
    reraise(type(exception), exception, tb=exc_tb, cause=cause)
  File "/mnt/f/python_lin/nail/env/lib/python3.6/site-packages/sqlalchemy/util/compat.py", line 152, in reraise
    raise value.with_traceback(tb)
  File "/mnt/f/python_lin/nail/env/lib/python3.6/site-packages/sqlalchemy/engine/base.py", line 1244, in _execute_context
    cursor, statement, parameters, context
  File "/mnt/f/python_lin/nail/env/lib/python3.6/site-packages/sqlalchemy/engine/default.py", line 552, in do_execute
    cursor.execute(statement, parameters)
sqlalchemy.exc.IntegrityError: (sqlite3.IntegrityError) UNIQUE constraint failed: news.url
[SQL: INSERT INTO news (title, url, published, source, text) VALUES (?, ?, ?, ?, ?)]
[parameters: ('Дженнифер Лопес показала маникюр, который мы все будем носить этой осенью', 'https://7days.ru/news/dzhennifer-lopes-pokazala-manikyur-kotoryy-my-vse-budem-nosit-etoy-osenyu.htm?link=search', '2019-08-29 20:30:00.000000', 'https://7days.ru', None)]
(Background on this error at: http://sqlalche.me/e/gkpj)
2019-09-16 13:24:35,393 INFO: Nail startup [in /mnt/f/python_lin/nail/app/__init__.py:89]
