2019-09-13 18:41:22,341 ERROR: Exception on /user/login [GET] [in /mnt/f/python_lin/nail/env/lib/python3.6/site-packages/flask/app.py:1891]
Traceback (most recent call last):
  File "/mnt/f/python_lin/nail/env/lib/python3.6/site-packages/flask/app.py", line 2446, in wsgi_app
    response = self.full_dispatch_request()
  File "/mnt/f/python_lin/nail/env/lib/python3.6/site-packages/flask/app.py", line 1951, in full_dispatch_request
    rv = self.handle_user_exception(e)
  File "/mnt/f/python_lin/nail/env/lib/python3.6/site-packages/flask/app.py", line 1820, in handle_user_exception
    reraise(exc_type, exc_value, tb)
  File "/mnt/f/python_lin/nail/env/lib/python3.6/site-packages/flask/_compat.py", line 39, in reraise
    raise value
  File "/mnt/f/python_lin/nail/env/lib/python3.6/site-packages/flask/app.py", line 1949, in full_dispatch_request
    rv = self.dispatch_request()
  File "/mnt/f/python_lin/nail/env/lib/python3.6/site-packages/flask/app.py", line 1935, in dispatch_request
    return self.view_functions[rule.endpoint](**req.view_args)
  File "/mnt/f/python_lin/nail/app/user/routes.py", line 25, in login
    form = LoginForm()
  File "/mnt/f/python_lin/nail/env/lib/python3.6/site-packages/wtforms/form.py", line 212, in __call__
    return type.__call__(cls, *args, **kwargs)
  File "/mnt/f/python_lin/nail/env/lib/python3.6/site-packages/flask_wtf/form.py", line 88, in __init__
    super(FlaskForm, self).__init__(formdata=formdata, **kwargs)
  File "/mnt/f/python_lin/nail/env/lib/python3.6/site-packages/wtforms/form.py", line 272, in __init__
    super(Form, self).__init__(self._unbound_fields, meta=meta_obj, prefix=prefix)
  File "/mnt/f/python_lin/nail/env/lib/python3.6/site-packages/wtforms/form.py", line 52, in __init__
    field = meta.bind_field(self, unbound_field, options)
  File "/mnt/f/python_lin/nail/env/lib/python3.6/site-packages/wtforms/meta.py", line 27, in bind_field
    return unbound_field.bind(form=form, **options)
  File "/mnt/f/python_lin/nail/env/lib/python3.6/site-packages/wtforms/fields/core.py", line 353, in bind
    return self.field_class(*self.args, **kw)
  File "/mnt/f/python_lin/nail/env/lib/python3.6/site-packages/wtforms/fields/core.py", line 702, in __init__
    super(BooleanField, self).__init__(label, validators, **kwargs)
TypeError: __init__() got an unexpected keyword argument 'disable'
2019-09-13 18:42:09,119 INFO: Nail startup [in /mnt/f/python_lin/nail/app/__init__.py:87]
2019-09-13 18:42:10,882 ERROR: Exception on /user/login [GET] [in /mnt/f/python_lin/nail/env/lib/python3.6/site-packages/flask/app.py:1891]
Traceback (most recent call last):
  File "/mnt/f/python_lin/nail/env/lib/python3.6/site-packages/flask/app.py", line 2446, in wsgi_app
    response = self.full_dispatch_request()
  File "/mnt/f/python_lin/nail/env/lib/python3.6/site-packages/flask/app.py", line 1951, in full_dispatch_request
    rv = self.handle_user_exception(e)
  File "/mnt/f/python_lin/nail/env/lib/python3.6/site-packages/flask/app.py", line 1820, in handle_user_exception
    reraise(exc_type, exc_value, tb)
  File "/mnt/f/python_lin/nail/env/lib/python3.6/site-packages/flask/_compat.py", line 39, in reraise
    raise value
  File "/mnt/f/python_lin/nail/env/lib/python3.6/site-packages/flask/app.py", line 1949, in full_dispatch_request
    rv = self.dispatch_request()
  File "/mnt/f/python_lin/nail/env/lib/python3.6/site-packages/flask/app.py", line 1935, in dispatch_request
    return self.view_functions[rule.endpoint](**req.view_args)
  File "/mnt/f/python_lin/nail/app/user/routes.py", line 25, in login
    form = LoginForm()
  File "/mnt/f/python_lin/nail/env/lib/python3.6/site-packages/wtforms/form.py", line 212, in __call__
    return type.__call__(cls, *args, **kwargs)
  File "/mnt/f/python_lin/nail/env/lib/python3.6/site-packages/flask_wtf/form.py", line 88, in __init__
    super(FlaskForm, self).__init__(formdata=formdata, **kwargs)
  File "/mnt/f/python_lin/nail/env/lib/python3.6/site-packages/wtforms/form.py", line 272, in __init__
    super(Form, self).__init__(self._unbound_fields, meta=meta_obj, prefix=prefix)
  File "/mnt/f/python_lin/nail/env/lib/python3.6/site-packages/wtforms/form.py", line 52, in __init__
    field = meta.bind_field(self, unbound_field, options)
  File "/mnt/f/python_lin/nail/env/lib/python3.6/site-packages/wtforms/meta.py", line 27, in bind_field
    return unbound_field.bind(form=form, **options)
  File "/mnt/f/python_lin/nail/env/lib/python3.6/site-packages/wtforms/fields/core.py", line 353, in bind
    return self.field_class(*self.args, **kw)
  File "/mnt/f/python_lin/nail/env/lib/python3.6/site-packages/wtforms/fields/core.py", line 702, in __init__
    super(BooleanField, self).__init__(label, validators, **kwargs)
TypeError: __init__() got an unexpected keyword argument 'enable'
2019-09-13 18:44:46,538 INFO: Nail startup [in /mnt/f/python_lin/nail/app/__init__.py:87]
2019-09-13 18:47:29,053 INFO: Nail startup [in /mnt/f/python_lin/nail/app/__init__.py:87]
2019-09-13 18:48:13,245 INFO: Nail startup [in /mnt/f/python_lin/nail/app/__init__.py:87]
2019-09-13 18:53:14,114 INFO: Nail startup [in /mnt/f/python_lin/nail/app/__init__.py:87]
2019-09-14 16:35:59,270 INFO: Nail startup [in /mnt/f/python_lin/nail/app/__init__.py:90]
2019-09-14 16:39:13,909 INFO: Nail startup [in /mnt/f/python_lin/nail/app/__init__.py:90]
2019-09-14 16:44:13,222 INFO: Nail startup [in /mnt/f/python_lin/nail/app/__init__.py:90]
2019-09-14 16:45:25,140 INFO: Nail startup [in /mnt/f/python_lin/nail/app/__init__.py:90]
2019-09-14 16:46:47,537 INFO: Nail startup [in /mnt/f/python_lin/nail/app/__init__.py:90]
