2019-09-13 18:03:37,747 ERROR: Exception on /user/login [GET] [in /mnt/f/python_lin/nail/env/lib/python3.6/site-packages/flask/app.py:1891]
Traceback (most recent call last):
  File "/mnt/f/python_lin/nail/env/lib/python3.6/site-packages/flask/app.py", line 2446, in wsgi_app
    response = self.full_dispatch_request()
  File "/mnt/f/python_lin/nail/env/lib/python3.6/site-packages/flask/app.py", line 1951, in full_dispatch_request
    rv = self.handle_user_exception(e)
  File "/mnt/f/python_lin/nail/env/lib/python3.6/site-packages/flask/app.py", line 1820, in handle_user_exception
    reraise(exc_type, exc_value, tb)
  File "/mnt/f/python_lin/nail/env/lib/python3.6/site-packages/flask/_compat.py", line 39, in reraise
    raise value
  File "/mnt/f/python_lin/nail/env/lib/python3.6/site-packages/flask/app.py", line 1949, in full_dispatch_request
    rv = self.dispatch_request()
  File "/mnt/f/python_lin/nail/env/lib/python3.6/site-packages/flask/app.py", line 1935, in dispatch_request
    return self.view_functions[rule.endpoint](**req.view_args)
  File "/mnt/f/python_lin/nail/app/user/routes.py", line 37, in login
    return render_template('user/login.html', title=titleVar, form=form)
  File "/mnt/f/python_lin/nail/env/lib/python3.6/site-packages/flask/templating.py", line 140, in render_template
    ctx.app,
  File "/mnt/f/python_lin/nail/env/lib/python3.6/site-packages/flask/templating.py", line 120, in _render
    rv = template.render(context)
  File "/mnt/f/python_lin/nail/env/lib/python3.6/site-packages/jinja2/asyncsupport.py", line 76, in render
    return original_render(self, *args, **kwargs)
  File "/mnt/f/python_lin/nail/env/lib/python3.6/site-packages/jinja2/environment.py", line 1008, in render
    return self.environment.handle_exception(exc_info, True)
  File "/mnt/f/python_lin/nail/env/lib/python3.6/site-packages/jinja2/environment.py", line 780, in handle_exception
    reraise(exc_type, exc_value, tb)
  File "/mnt/f/python_lin/nail/env/lib/python3.6/site-packages/jinja2/_compat.py", line 37, in reraise
    raise value.with_traceback(tb)
  File "/mnt/f/python_lin/nail/app/templates/user/login.html", line 36, in top-level template code
    {% for error in form.password.errors %}
  File "/mnt/f/python_lin/nail/app/templates/base.html", line 1, in top-level template code
    {% extends 'bootstrap/base.html' %}
  File "/mnt/f/python_lin/nail/env/lib/python3.6/site-packages/flask_bootstrap/templates/bootstrap/base.html", line 1, in top-level template code
    {% block doc -%}
  File "/mnt/f/python_lin/nail/env/lib/python3.6/site-packages/flask_bootstrap/templates/bootstrap/base.html", line 4, in block "doc"
    {%- block html %}
  File "/mnt/f/python_lin/nail/env/lib/python3.6/site-packages/flask_bootstrap/templates/bootstrap/base.html", line 20, in block "html"
    {% block body -%}
  File "/mnt/f/python_lin/nail/env/lib/python3.6/site-packages/flask_bootstrap/templates/bootstrap/base.html", line 23, in block "body"
    {% block content -%}
  File "/mnt/f/python_lin/nail/app/templates/base.html", line 17, in block "content"
    {% block app_content %}
  File "/mnt/f/python_lin/nail/app/templates/user/login.html", line 19, in block "app_content"
    <a href="{{ url_for('user.register') }}">{{ _('Зарегистрируйтесь!') }}</a>
  File "/mnt/f/python_lin/nail/env/lib/python3.6/site-packages/flask/helpers.py", line 370, in url_for
    return appctx.app.handle_url_build_error(error, endpoint, values)
  File "/mnt/f/python_lin/nail/env/lib/python3.6/site-packages/flask/app.py", line 2215, in handle_url_build_error
    reraise(exc_type, exc_value, tb)
  File "/mnt/f/python_lin/nail/env/lib/python3.6/site-packages/flask/_compat.py", line 39, in reraise
    raise value
  File "/mnt/f/python_lin/nail/env/lib/python3.6/site-packages/flask/helpers.py", line 358, in url_for
    endpoint, values, method=method, force_external=external
  File "/mnt/f/python_lin/nail/env/lib/python3.6/site-packages/werkzeug/routing.py", line 2020, in build
    raise BuildError(endpoint, values, method, self)
werkzeug.routing.BuildError: Could not build url for endpoint 'user.register'. Did you mean 'user.register_user' instead?
2019-09-13 18:09:40,464 INFO: Nail startup [in /mnt/f/python_lin/nail/app/__init__.py:87]
2019-09-13 18:11:43,742 INFO: Nail startup [in /mnt/f/python_lin/nail/app/__init__.py:87]
2019-09-13 18:12:04,862 ERROR: Exception on /user/register_user/eyJ0eXAiOiJKV1QiLCJhbGciOiJIUzI1NiJ9.eyJyZWdpc3Rlcl91c2VyIjoyLCJleHAiOjE1NjgzODgxMTUuMDAxMzU0fQ.KlR5BI4iHyPGuMIeyGtQOmS9eZw91AW4brS4uMZ3xvs [GET] [in /mnt/f/python_lin/nail/env/lib/python3.6/site-packages/flask/app.py:1891]
Traceback (most recent call last):
  File "/mnt/f/python_lin/nail/env/lib/python3.6/site-packages/flask/app.py", line 2446, in wsgi_app
    response = self.full_dispatch_request()
  File "/mnt/f/python_lin/nail/env/lib/python3.6/site-packages/flask/app.py", line 1951, in full_dispatch_request
    rv = self.handle_user_exception(e)
  File "/mnt/f/python_lin/nail/env/lib/python3.6/site-packages/flask/app.py", line 1820, in handle_user_exception
    reraise(exc_type, exc_value, tb)
  File "/mnt/f/python_lin/nail/env/lib/python3.6/site-packages/flask/_compat.py", line 39, in reraise
    raise value
  File "/mnt/f/python_lin/nail/env/lib/python3.6/site-packages/flask/app.py", line 1949, in full_dispatch_request
    rv = self.dispatch_request()
  File "/mnt/f/python_lin/nail/env/lib/python3.6/site-packages/flask/app.py", line 1935, in dispatch_request
    return self.view_functions[rule.endpoint](**req.view_args)
  File "/mnt/f/python_lin/nail/app/user/routes.py", line 105, in register_user
    if not user:
NameError: name 'user' is not defined
2019-09-13 18:14:17,544 INFO: Nail startup [in /mnt/f/python_lin/nail/app/__init__.py:87]
2019-09-13 18:14:43,708 ERROR: Exception on /user/register_user/eyJ0eXAiOiJKV1QiLCJhbGciOiJIUzI1NiJ9.eyJyZWdpc3Rlcl91c2VyIjoyLCJleHAiOjE1NjgzODgyNjYuNzk3NTk4fQ.LL_Ytl2HrejRsfiwMwSc-2A0iILVHg6jptqbWioJKSY [GET] [in /mnt/f/python_lin/nail/env/lib/python3.6/site-packages/flask/app.py:1891]
Traceback (most recent call last):
  File "/mnt/f/python_lin/nail/env/lib/python3.6/site-packages/flask/app.py", line 2446, in wsgi_app
    response = self.full_dispatch_request()
  File "/mnt/f/python_lin/nail/env/lib/python3.6/site-packages/flask/app.py", line 1951, in full_dispatch_request
    rv = self.handle_user_exception(e)
  File "/mnt/f/python_lin/nail/env/lib/python3.6/site-packages/flask/app.py", line 1820, in handle_user_exception
    reraise(exc_type, exc_value, tb)
  File "/mnt/f/python_lin/nail/env/lib/python3.6/site-packages/flask/_compat.py", line 39, in reraise
    raise value
  File "/mnt/f/python_lin/nail/env/lib/python3.6/site-packages/flask/app.py", line 1949, in full_dispatch_request
    rv = self.dispatch_request()
  File "/mnt/f/python_lin/nail/env/lib/python3.6/site-packages/flask/app.py", line 1935, in dispatch_request
    return self.view_functions[rule.endpoint](**req.view_args)
  File "/mnt/f/python_lin/nail/app/user/routes.py", line 105, in register_user
    if not user:
NameError: name 'user' is not defined
2019-09-13 18:15:59,083 INFO: Nail startup [in /mnt/f/python_lin/nail/app/__init__.py:87]
2019-09-13 18:16:47,340 ERROR: Exception on /user/register_user/eyJ0eXAiOiJKV1QiLCJhbGciOiJIUzI1NiJ9.eyJyZWdpc3Rlcl91c2VyIjoyLCJleHAiOjE1NjgzODgzNzQuNDM4Nzc0fQ.9HCFZJFEVFdNw9IteJiqYYlQNqexbgZwbKNLthRCgAo [POST] [in /mnt/f/python_lin/nail/env/lib/python3.6/site-packages/flask/app.py:1891]
Traceback (most recent call last):
  File "/mnt/f/python_lin/nail/env/lib/python3.6/site-packages/flask/app.py", line 2446, in wsgi_app
    response = self.full_dispatch_request()
  File "/mnt/f/python_lin/nail/env/lib/python3.6/site-packages/flask/app.py", line 1951, in full_dispatch_request
    rv = self.handle_user_exception(e)
  File "/mnt/f/python_lin/nail/env/lib/python3.6/site-packages/flask/app.py", line 1820, in handle_user_exception
    reraise(exc_type, exc_value, tb)
  File "/mnt/f/python_lin/nail/env/lib/python3.6/site-packages/flask/_compat.py", line 39, in reraise
    raise value
  File "/mnt/f/python_lin/nail/env/lib/python3.6/site-packages/flask/app.py", line 1949, in full_dispatch_request
    rv = self.dispatch_request()
  File "/mnt/f/python_lin/nail/env/lib/python3.6/site-packages/flask/app.py", line 1935, in dispatch_request
    return self.view_functions[rule.endpoint](**req.view_args)
  File "/mnt/f/python_lin/nail/app/user/routes.py", line 109, in register_user
    user.set_password(form.password.data)
NameError: name 'user' is not defined
2019-09-13 18:18:25,825 INFO: Nail startup [in /mnt/f/python_lin/nail/app/__init__.py:87]
2019-09-13 18:19:39,721 INFO: Nail startup [in /mnt/f/python_lin/nail/app/__init__.py:87]
2019-09-13 18:23:16,914 INFO: Nail startup [in /mnt/f/python_lin/nail/app/__init__.py:87]
2019-09-13 18:31:43,558 INFO: Nail startup [in /mnt/f/python_lin/nail/app/__init__.py:87]
2019-09-13 18:37:52,208 INFO: Nail startup [in /mnt/f/python_lin/nail/app/__init__.py:87]
2019-09-13 18:39:55,779 INFO: Nail startup [in /mnt/f/python_lin/nail/app/__init__.py:87]
2019-09-13 18:41:13,066 INFO: Nail startup [in /mnt/f/python_lin/nail/app/__init__.py:87]
