2019-09-16 13:44:50,689 ERROR: Exception on / [GET] [in /mnt/f/python_lin/nail/env/lib/python3.6/site-packages/flask/app.py:1891]
Traceback (most recent call last):
  File "/mnt/f/python_lin/nail/env/lib/python3.6/site-packages/sqlalchemy/engine/base.py", line 1244, in _execute_context
    cursor, statement, parameters, context
  File "/mnt/f/python_lin/nail/env/lib/python3.6/site-packages/sqlalchemy/engine/default.py", line 552, in do_execute
    cursor.execute(statement, parameters)
sqlite3.OperationalError: disk I/O error

The above exception was the direct cause of the following exception:

Traceback (most recent call last):
  File "/mnt/f/python_lin/nail/env/lib/python3.6/site-packages/flask/app.py", line 2446, in wsgi_app
    response = self.full_dispatch_request()
  File "/mnt/f/python_lin/nail/env/lib/python3.6/site-packages/flask/app.py", line 1951, in full_dispatch_request
    rv = self.handle_user_exception(e)
  File "/mnt/f/python_lin/nail/env/lib/python3.6/site-packages/flask/app.py", line 1820, in handle_user_exception
    reraise(exc_type, exc_value, tb)
  File "/mnt/f/python_lin/nail/env/lib/python3.6/site-packages/flask/_compat.py", line 39, in reraise
    raise value
  File "/mnt/f/python_lin/nail/env/lib/python3.6/site-packages/flask/app.py", line 1947, in full_dispatch_request
    rv = self.preprocess_request()
  File "/mnt/f/python_lin/nail/env/lib/python3.6/site-packages/flask/app.py", line 2241, in preprocess_request
    rv = func()
  File "/mnt/f/python_lin/nail/app/user/main/routes.py", line 20, in before_request
    if current_user.is_authenticated:
  File "/mnt/f/python_lin/nail/env/lib/python3.6/site-packages/werkzeug/local.py", line 348, in __getattr__
    return getattr(self._get_current_object(), name)
  File "/mnt/f/python_lin/nail/env/lib/python3.6/site-packages/werkzeug/local.py", line 307, in _get_current_object
    return self.__local()
  File "/mnt/f/python_lin/nail/env/lib/python3.6/site-packages/flask_login/utils.py", line 26, in <lambda>
    current_user = LocalProxy(lambda: _get_user())
  File "/mnt/f/python_lin/nail/env/lib/python3.6/site-packages/flask_login/utils.py", line 335, in _get_user
    current_app.login_manager._load_user()
  File "/mnt/f/python_lin/nail/env/lib/python3.6/site-packages/flask_login/login_manager.py", line 359, in _load_user
    return self.reload_user()
  File "/mnt/f/python_lin/nail/env/lib/python3.6/site-packages/flask_login/login_manager.py", line 321, in reload_user
    user = self.user_callback(user_id)
  File "/mnt/f/python_lin/nail/app/user/models.py", line 172, in load_user
    return User.query.get(int(id))
  File "/mnt/f/python_lin/nail/env/lib/python3.6/site-packages/sqlalchemy/orm/query.py", line 959, in get
    return self._get_impl(ident, loading.load_on_pk_identity)
  File "/mnt/f/python_lin/nail/env/lib/python3.6/site-packages/sqlalchemy/orm/query.py", line 1069, in _get_impl
    return db_load_fn(self, primary_key_identity)
  File "/mnt/f/python_lin/nail/env/lib/python3.6/site-packages/sqlalchemy/orm/loading.py", line 282, in load_on_pk_identity
    return q.one()
  File "/mnt/f/python_lin/nail/env/lib/python3.6/site-packages/sqlalchemy/orm/query.py", line 3292, in one
    ret = self.one_or_none()
  File "/mnt/f/python_lin/nail/env/lib/python3.6/site-packages/sqlalchemy/orm/query.py", line 3261, in one_or_none
    ret = list(self)
  File "/mnt/f/python_lin/nail/env/lib/python3.6/site-packages/sqlalchemy/orm/query.py", line 3334, in __iter__
    return self._execute_and_instances(context)
  File "/mnt/f/python_lin/nail/env/lib/python3.6/site-packages/sqlalchemy/orm/query.py", line 3359, in _execute_and_instances
    result = conn.execute(querycontext.statement, self._params)
  File "/mnt/f/python_lin/nail/env/lib/python3.6/site-packages/sqlalchemy/engine/base.py", line 988, in execute
    return meth(self, multiparams, params)
  File "/mnt/f/python_lin/nail/env/lib/python3.6/site-packages/sqlalchemy/sql/elements.py", line 287, in _execute_on_connection
    return connection._execute_clauseelement(self, multiparams, params)
  File "/mnt/f/python_lin/nail/env/lib/python3.6/site-packages/sqlalchemy/engine/base.py", line 1107, in _execute_clauseelement
    distilled_params,
  File "/mnt/f/python_lin/nail/env/lib/python3.6/site-packages/sqlalchemy/engine/base.py", line 1248, in _execute_context
    e, statement, parameters, cursor, context
  File "/mnt/f/python_lin/nail/env/lib/python3.6/site-packages/sqlalchemy/engine/base.py", line 1466, in _handle_dbapi_exception
    util.raise_from_cause(sqlalchemy_exception, exc_info)
  File "/mnt/f/python_lin/nail/env/lib/python3.6/site-packages/sqlalchemy/util/compat.py", line 398, in raise_from_cause
    reraise(type(exception), exception, tb=exc_tb, cause=cause)
  File "/mnt/f/python_lin/nail/env/lib/python3.6/site-packages/sqlalchemy/util/compat.py", line 152, in reraise
    raise value.with_traceback(tb)
  File "/mnt/f/python_lin/nail/env/lib/python3.6/site-packages/sqlalchemy/engine/base.py", line 1244, in _execute_context
    cursor, statement, parameters, context
  File "/mnt/f/python_lin/nail/env/lib/python3.6/site-packages/sqlalchemy/engine/default.py", line 552, in do_execute
    cursor.execute(statement, parameters)
sqlalchemy.exc.OperationalError: (sqlite3.OperationalError) disk I/O error
[SQL: SELECT user.id AS user_id, user.username AS user_username, user.email AS user_email, user.password_hash AS user_password_hash, user.about_me AS user_about_me, user.last_seen AS user_last_seen, user.email_confirmed AS user_email_confirmed, user.role AS user_role 
FROM user 
WHERE user.id = ?]
[parameters: (2,)]
(Background on this error at: http://sqlalche.me/e/e3q8)
2019-09-16 13:45:17,685 INFO: Nail startup [in /mnt/f/python_lin/nail/app/__init__.py:89]
2019-09-16 13:46:49,935 INFO: Nail startup [in /mnt/f/python_lin/nail/app/__init__.py:89]
2019-09-16 13:48:32,718 INFO: Nail startup [in /mnt/f/python_lin/nail/app/__init__.py:89]
